Workbook

Sheet Cover
A1: BORROWER DETAILS
A3: Parameter | B3: Details
A4: Borrower Name | B4: Kovai Medical Centre and Hospital Ltd.
A5: Location | B5: Coimbatore, Tamil Nadu
A6: Borrower Type | B6: Private Multi-Specialty Hospital
A7: Industry | B7: Healthcare / Medical Infrastructure
A8: Contact Person | B8: —
A9: Date of Proposal | B9: 46174
A12: ASSET DETAILS
A14: Parameter | B14: Details
A15: Asset Description | B15: ARTIS icono Biplane Neurovascular Cathlab
A16: Manufacturer | B16: Siemens Healthineers
A17: Asset Type | B17: Medical Equipment — Biplane Cathlab
A18: Asset Category | B18: Neurovascular Imaging System
A19: Purpose | B19: Diagnostic & Interventional Neurovascular Procedures
A20: Asset Location | B20: Kovai Medical Centre, Coimbatore
A23: LOAN STRUCTURE
A25: Parameter | B25: Details
A26: Loan Amount | B26: ₹3,000.00 L
A27: Interest Rate | B27: 10.25% per annum
A28: Tenure | B28: 72 Months (6 Years)
A29: EMI | B29: ₹55.96 L per month
A30: Repayment Mode | B30: Monthly EMI
A31: Processing Fee (3%) | B31: ₹90.00 L
A32: Security / Collateral | B32: Hypothecation of Cathlab Equipment
A35: TOTAL COST OF FINANCE
A37: Parameter | B37: Amount (₹ Lakhs)
A38: Principal | B38: 3000
A39: Total Interest Outflow | B39: 1028.87
A40: Processing Fee | B40: 90
A41: Total Cost of Finance | B41: 1118.87
A42: Total Outflow (Principal + Interest + Fee) | B42: 4118.87

Sheet PL
A1: STATEMENT OF PROFIT AND LOSS
A3: Particulars | B3: FY2024 (₹ in Lakhs) | C3: FY2025 (₹ in Lakhs) | D3: FY2026 (₹ in Lakhs) | E3: YoY Growth FY24-25 | F3: YoY Growth FY25-26 | G3: Margin FY2024 | H3: Margin FY2025 | I3: Margin FY2026
A4: INCOME
A5: Revenue from Operations | B5: 121955.27 | C5: 137111.3 | D5: 158415.16
A6: Other Operating Income | C6: 137.57 | D6: 148.52
A7: Other Income | B7: 2094.92 | C7: 2210.42 | D7: 2824.73
A8: Total Revenue | B8: 124050.19 | C8: 139321.72 | D8: 161388.41 | E8: =(C8-B8)/ABS(B8) -> 0.12310767 | F8: =(D8-C8)/ABS(C8) -> 0.15838657
A10: EXPENSES
A11: Cost of Medicines & Hospital Consumables | B11: 32389.87 | C11: 39601.11 | D11: 44807.9 | G11: =B11/B8 -> 0.26110295 | H11: =C11/C8 -> 0.28424218 | I11: =D11/D8 -> 0.27764014
A12: Consulting Charges to Doctors | B12: 17574.88 | C12: 19136.55 | D12: 22111.11 | G12: =B12/B8 -> 0.14167556 | H12: =C12/C8 -> 0.13735511 | I12: =D12/D8 -> 0.13700556
A13: Employee Benefits Expense | B13: 21946.54 | C13: 25118.15 | D13: 30648.45 | G13: =B13/B8 -> 0.17691662 | H13: =C13/C8 -> 0.18028883 | I13: =D13/D8 -> 0.1899049
A14: Finance Costs | B14: 3294.39 | C14: 3267.67 | D14: 3201.69 | G14: =B14/B8 -> 0.026556912 | H14: =C14/C8 -> 0.023454132 | I14: =D14/D8 -> 0.019838413
A15: Depreciation & Amortisation | B15: 9213.62 | C15: 9758.66 | D15: 10939.4 | G15: =B15/B8 -> 0.074273324 | H15: =C15/C8 -> 0.070044068 | I15: =D15/D8 -> 0.067783058
A16: Other Expenses | B16: 15875.22 | C16: 17443.22 | D16: 17110.72 | G16: =B16/B8 -> 0.12797417 | H16: =C16/C8 -> 0.12520101 | I16: =D16/D8 -> 0.10602199
A17: Total Expenses | B17: 100294.52 | C17: 111566.36 | D17: 128819.27 | E17: =(C17-B17)/ABS(B17) -> 0.1123874 | F17: =(D17-C17)/ABS(C17) -> 0.15464258
A19: EBIT | B19: =B22+B14 -> 27050.06 | C19: =C22+C14 -> 31023.03 | D19: =D22+D14 -> 35770.83 | E19: =(C19-B19)/ABS(B19) -> 0.14687472 | F19: =(D19-C19)/ABS(C19) -> 0.15304114
A20: EBITDA | B20: =B19+B15 -> 36263.68 | C20: =C19+C15 -> 40781.69 | D20: =D19+D15 -> 46710.23 | E20: =(C20-B20)/ABS(B20) -> 0.12458774 | F20: =(D20-C20)/ABS(C20) -> 0.14537259
A22: Profit Before Tax | B22: 23755.67 | C22: 27755.36 | D22: 32569.14 | E22: =(C22-B22)/ABS(B22) -> 0.1683678 | F22: =(D22-C22)/ABS(C22) -> 0.17343605 | G22: =B22/B8 -> 0.19150047 | H22: =C22/C8 -> 0.19921775 | I22: =D22/D8 -> 0.20180594
A24: Current Tax | B24: 5633.1 | C24: 6729.9 | D24: 7962.54 | E24: =(C24-B24)/ABS(B24) -> 0.19470629 | F24: =(D24-C24)/ABS(C24) -> 0.18315874
A25: Prior Year Tax | B25: -65.65 | C25: 27.8 | D25: -44.76
A26: Deferred Tax | B26: 215.15 | C26: 103.04 | D26: 205.36
A27: Total Tax Expense | B27: 5782.6 | C27: 6860.74 | D27: 8123.14 | E27: =(C27-B27)/ABS(B27) -> 0.18644554 | F27: =(D27-C27)/ABS(C27) -> 0.18400347
A29: Profit After Tax | B29: 17973.07 | C29: 20894.62 | D29: 24446 | E29: =(C29-B29)/ABS(B29) -> 0.16255153 | F29: =(D29-C29)/ABS(C29) -> 0.16996624 | G29: =B29/B8 -> 0.14488547 | H29: =C29/C8 -> 0.14997389 | I29: =D29/D8 -> 0.15147308
A31: OTHER COMPREHENSIVE INCOME
A32: Remeasurement of post-employment benefit obligations | B32: 75.36 | C32: -47.5 | D32: -66.94
A33: Change in equity instruments (FVOCI) | B33: 18.95 | C33: -8.52 | D33: 10.07
A34: Income tax on OCI items | B34: -23.74 | C34: 18.01 | D34: 15.39
A35: Total OCI | B35: 70.57 | C35: -38.01 | D35: -41.48
A37: Total Comprehensive Income | B37: 18043.64 | C37: 20856.61 | D37: 24404.52 | E37: =(C37-B37)/ABS(B37) -> 0.15589814 | F37: =(D37-C37)/ABS(C37) -> 0.17010962 | G37: =B37/B8 -> 0.14545435 | H37: =C37/C8 -> 0.14970107 | I37: =D37/D8 -> 0.15121606
A39: Basic & Diluted EPS (Rs.) | B39: 164.25 | C39: 190.95 | D39: 223.41 | E39: =(C39-B39)/ABS(B39) -> 0.16255708 | F39: =(D39-C39)/ABS(C39) -> 0.16999214
A40: Note: FY2024 Other Operating Income not separately disclosed - included within Revenue from Operations.
A41: Note: FY2025 Other Expenses classification differs from quarterly format due to dietary consumed reclassification.

Sheet BS
A1: BALANCE SHEET
A3: Particulars | B3: FY2024 (₹ in Lakhs) | C3: FY2025 (₹ in Lakhs) | D3: FY2026 (₹ in Lakhs) | E3: YoY Growth FY24-25 | F3: YoY Growth FY25-26
A4: ASSETS
A5: Non-Current Assets
A6: Property Plant and Equipment | B6: 108790.74 | C6: 125485.41 | D6: 144110.75 | E6: =(C6-B6)/ABS(B6) -> 0.15345672 | F6: =(D6-C6)/ABS(C6) -> 0.14842634
A7: Right of Use Assets | B7: 2829.11 | C7: 2463.66 | D7: 2413.36 | E7: =(C7-B7)/ABS(B7) -> -0.1291749 | F7: =(D7-C7)/ABS(C7) -> -0.020416778
A8: Capital Work-in-Progress | B8: 3863.1 | C8: 14957.2 | D8: 13496.02 | E8: =(C8-B8)/ABS(B8) -> 2.8718128 | F8: =(D8-C8)/ABS(C8) -> -0.097690744
A9: Intangible Assets | B9: 148.34 | C9: 320.54 | D9: 828.24 | E9: =(C9-B9)/ABS(B9) -> 1.1608467 | F9: =(D9-C9)/ABS(C9) -> 1.5838897
A10: Investments | B10: 45.35 | C10: 34.3 | D10: 51.87 | E10: =(C10-B10)/ABS(B10) -> -0.24366042 | F10: =(D10-C10)/ABS(C10) -> 0.5122449
A11: Other Financial Assets | B11: 1498.53 | C11: 1762.01 | D11: 1856.26 | E11: =(C11-B11)/ABS(B11) -> 0.17582564 | F11: =(D11-C11)/ABS(C11) -> 0.053490048
A12: Other Non-Current Assets | B12: 1606.81 | C12: 1474.07 | D12: 1740.36 | E12: =(C12-B12)/ABS(B12) -> -0.082610887 | F12: =(D12-C12)/ABS(C12) -> 0.18064949
A13: Total Non-Current Assets | B13: 118781.98 | C13: 146940.07 | D13: 164514.32 | E13: =(C13-B13)/ABS(B13) -> 0.23705692 | F13: =(D13-C13)/ABS(C13) -> 0.11960148
A15: Current Assets
A16: Inventories | B16: 1469.85 | C16: 1561.58 | D16: 2025.09
A17: Trade Receivables | B17: 1680.54 | C17: 3083.62 | D17: 3808.02
A18: Cash and Cash Equivalents | B18: 5960.21 | C18: 1429.9 | D18: 6372.38
A19: Bank Balances other than Cash and Cash Equivalents | B19: 15145.66 | C19: 25962.92 | D19: 28348.42
A20: Other Financial Assets (Current) | B20: 337.74 | C20: 400.94 | D20: 562.52
A21: Other Current Assets | B21: 447.42 | C21: 612.41 | D21: 977.36
A22: Total Current Assets | B22: 25041.42 | C22: 33051.37 | D22: 42093.79 | E22: =(C22-B22)/ABS(B22) -> 0.31986804 | F22: =(D22-C22)/ABS(C22) -> 0.27358684
A24: TOTAL ASSETS | B24: 143823.4 | C24: 179991.44 | D24: 206608.11 | E24: =(C24-B24)/ABS(B24) -> 0.25147535 | F24: =(D24-C24)/ABS(C24) -> 0.14787742
A26: EQUITY AND LIABILITIES
A27: Equity
A28: Equity Share Capital | B28: 1094.23 | C28: 1094.23 | D28: 1094.23
A29: Other Equity | B29: 87759.62 | C29: 107522 | D29: 130832.29
A30: Total Equity | B30: 88853.85 | C30: 108616.23 | D30: 131926.52 | E30: =(C30-B30)/ABS(B30) -> 0.22241445 | F30: =(D30-C30)/ABS(C30) -> 0.21461148
A32: Non-Current Liabilities
A33: Borrowings (Non-Current) | B33: 25318.08 | C33: 34832.9 | D33: 31735.41
A34: Lease Liabilities (Non-Current) | B34: 3334.74 | C34: 3054.14 | D34: 2986.82
A35: Other Financial Liabilities (Non-Current) | B35: 45.78 | C35: 255.68 | D35: 112.51
A36: Provisions (Non-Current) | B36: 2020.95 | C36: 2363.5 | D36: 3101.45
A37: Deferred Tax Liabilities (Net) | B37: 3789.41 | C37: 3874.44 | D37: 4064.41
A38: Other Non-Current Liabilities | B38: 6.5 | C38: 8.86 | D38: 6.91
A39: Total Non-Current Liabilities | B39: 34515.46 | C39: 44389.52 | D39: 42007.51 | E39: =(C39-B39)/ABS(B39) -> 0.28607644 | F39: =(D39-C39)/ABS(C39) -> -0.05366154
A41: Current Liabilities
A42: Borrowings (Current) | B42: 2122.01 | C42: 3356.98 | D42: 5192.73
A43: Lease Liabilities (Current) | B43: 260.77 | C43: 289.74 | D43: 359.76
A44: Trade Payables - Micro and Small Enterprises | B44: 188.06 | C44: 414.64 | D44: 373.92
A45: Trade Payables - Others | B45: 2451.37 | C45: 2534.18 | D45: 2072.04
A46: Other Financial Liabilities (Current) | B46: 8825.27 | C46: 12550.88 | D46: 17726.54
...

Sheet CF
A1: CASH FLOW STATEMENT
A3: Particulars | B3: FY2024 (₹ in Lakhs) | C3: FY2025 (₹ in Lakhs) | D3: FY2026 (₹ in Lakhs) | E3: YoY Growth FY24-25 | F3: YoY Growth FY25-26
A4: A. CASH FLOW FROM OPERATING ACTIVITIES
A5: Profit Before Tax | B5: 23755.67 | C5: 27755.36 | D5: 32569.14
A7: Adjustments for:
A8: Depreciation and Amortisation | B8: 9213.62 | C8: 9758.66 | D8: 10939.4
A9: Exchange Fluctuation Loss/(Gain) Net | B9: 0.16 | C9: 2.7 | D9: -8.8
A10: Finance Cost | B10: 3276.08 | C10: 3263.91 | D10: 3193.28
A11: Dividend Income | B11: -0.73 | C11: -0.98 | D11: -1.22
A12: Interest Income | D12: -2097.55
A13: Non Cash Transactions | B13: -185.82 | C13: -46.13 | D13: -80.69
A14: Loss/(Profit) on Sale of PPE (Net) | B14: -4.5 | C14: 18.6 | D14: 148.79
A15: Total Adjustments | B15: 12298.81 | C15: 12996.76 | D15: 12093.21
A17: Operating Profit Before Working Capital Changes | B17: 36054.48 | C17: 40752.12 | D17: 44662.35
A19: (Increase)/Decrease in Non-Current & Current Financial Assets | B19: 1835.89 | C19: -1857.89 | D19: -1470.35
A20: (Increase)/Decrease in Other Non-Current & Current Assets | B20: 121.78 | C20: -188.34 | D20: -364.95
A21: Increase/(Decrease) in Non-Current & Current Financial Liabilities | B21: 1948.45 | C21: 1520.22 | D21: 1578.72
A22: Increase/(Decrease) in Other Non-Current & Current Liabilities | B22: 164.07 | C22: 1162.28 | D22: 173.63
A23: Total Working Capital Changes | B23: 4070.19 | C23: 636.27 | D23: -82.95
A25: Cash Generated from Operations | B25: 40124.67 | C25: 41388.39 | D25: 44579.4 | E25: =(C25-B25)/ABS(B25) -> 0.031494838 | F25: =(D25-C25)/ABS(C25) -> 0.077099158
A26: Income Tax Paid | B26: -5711.41 | C26: -6096.92 | D26: -8395.97 | E26: =(C26-B26)/ABS(B26) -> -0.067498218 | F26: =(D26-C26)/ABS(C26) -> -0.37708384
A27: Net Cash from Operating Activities (A) | B27: 34413.26 | C27: 35291.47 | D27: 36183.43 | E27: =(C27-B27)/ABS(B27) -> 0.025519524 | F27: =(D27-C27)/ABS(C27) -> 0.025274096
A29: B. CASH FLOW FROM INVESTING ACTIVITIES
A30: Purchase of PPE Capital Work-in-Progress and Intangible Assets | B30: -13842.26 | C30: -35309.94 | D30: -25195.45 | E30: =(C30-B30)/ABS(B30) -> -1.5508797 | F30: =(D30-C30)/ABS(C30) -> 0.2864488
A31: Proceeds from Sale of PPE | B31: 24.3 | C31: 92.54 | D31: 85.7
A32: Investment in/(Sale of) Equity Instruments | C32: 2.53 | D32: -7.5
A33: Interest Income | D33: 2097.55
A34: Dividend Income | B34: 0.73 | C34: 0.98 | D34: 1.22
A35: Net Cash from/(used in) Investing Activities (B) | B35: -13817.23 | C35: -35213.89 | D35: -23018.48 | E35: =(C35-B35)/ABS(B35) -> -1.5485492 | F35: =(D35-C35)/ABS(C35) -> 0.34632385
A37: C. CASH FLOW FROM FINANCING ACTIVITIES
A38: Long Term Borrowings Net of Repayment | B38: -19849.91 | C38: 10749.79 | D38: -1261.73
A39: Short Term Borrowings (Net) | B39: -9.07
A40: Repayment of Lease Liabilities | B40: -539.64 | C40: -538.78 | D40: -605.99
A41: Finance Cost Paid | B41: -2860.16 | C41: -2927.36 | D41: -2877.89 | E41: =(C41-B41)/ABS(B41) -> -0.023495189 | F41: =(D41-C41)/ABS(C41) -> 0.016899186
A42: Dividend Paid | B42: -1090.39 | C42: -1074.28 | D42: -1091.36 | E42: =(C42-B42)/ABS(B42) -> 0.01477453 | F42: =(D42-C42)/ABS(C42) -> -0.015899021
A43: Net Cash from/(used in) Financing Activities (C) | B43: -24349.17 | C43: 6209.37 | D43: -5836.97 | E43: =(C43-B43)/ABS(B43) -> 1.2550136 | F43: =(D43-C43)/ABS(C43) -> -1.9400261
A45: Net Increase/(Decrease) in Cash and Cash Equivalents (A+B+C) | B45: -3753.14 | C45: 6286.95 | D45: 7327.98 | E45: =(C45-B45)/ABS(B45) -> 2.6751174 | F45: =(D45-C45)/ABS(C45) -> 0.16558586
A47: Cash and Bank Balance at Beginning of Year | B47: 24859.01 | C47: 21105.87 | D47: 27392.82
A48: Less: Bank Balances not considered as Cash and Cash Equivalents (Ind AS 7) | B48: 15145.66 | C48: 25962.92 | D48: 28348.42
A49: Cash and Cash Equivalents at End of Year | B49: 5960.21 | C49: 1429.9 | D49: 6372.38 | E49: =(C49-B49)/ABS(B49) -> -0.76009235 | F49: =(D49-C49)/ABS(C49) -> 3.4565214
...

Sheet Norm
A1: Asset Base & Tangible Net Worth
A3: Particulars | B3: Adjustment | C3: Source | D3: Reason
A4: Disputed Property | B4: 5931 | C4: Note 1 & 2 (Disclosures) | D4: Written down to zero due to ongoing High Court stamp duty litigation.
A5: Unregistered Auction Assets | B5: 12068.63 | C5: Note 1 & 2 (Disclosures) | D5: Written down to zero; title transfer is stalled at the NCLT.
A6: Delayed New OPD Block | B6: 5594.35 | C6: Note 4 (CWIP Aging Schedule)
A7: Computer Software & Net Intangibles | B7: 320.54 | C7: Note 5 (Intangible Assets) | D7: Written down to zero; asset holds zero secondary market liquidation value.
A8: Software Under Development | B8: 442.88 | C8: Note 6 (Intangibles Under Dev.) | D8: Written down to zero; incomplete software assets cannot be liquidated during distress.
A9: Capital Advances | B9: 1424.04 | C9: Note 9 (Other Non-Current Assets) | D9: Written down to zero; cash is held by third-party construction vendors and cannot be recalled.
A10: Level 3 Corporate Investments | B10: 6 | C10: Note 7 (Investments) | D10: Written down to zero due to restricted transferability.
A11: Deposits Paid Under Protest | B11: 283.87 | C11: Note 8 (Other Financial Assets) | D11: Stripped from assets; cash is locked up in long-term tax and provident fund litigation.
C13: Adjusted Non-Current Assets Figure
A14: Adjustable Non-Current Assets Figure | B14: =SUM(B4:B11) -> 26071.31 | C14: =BS!C13-B14 -> 120868.76
A18: Current Assets and Cash Reserve
A20: Particulars | B20: Adjustment | C20: Source | D20: Reason
A21: Restricted Escrow Cash Balances | B21: 270.1 | C21: Note 13 (Bank Balances) | D21: Deducted from liquid assets; cash is restricted for bank guarantees, dividend accounts, and CSR mandates.
A22: Advance Course Student Fees | B22: 5739.07 | C22: Note 28 (Other Current Liabilities) | D22: Isolated from general corporate cash; must be held to fund active academic operations.
A23: Unbilled & Aged Receivables | B23: 1030.15 | C23: Note 11 (Trade Receivables Aging) | D23: Written down to zero; excludes unbilled revenue and all balances past due over 6 months from capital calculations.
C25: Adjusted Figures
A26: Total Adjustable Cash | B26: =B21+B22 -> 6009.17 | C26: =BS!C18+BS!C19-B26 -> 21383.65
A28: Total Adjustable Current Assets | B28: =B23+B26 -> 7039.32 | C28: =BS!C22-B28 -> 26012.05
A30: Total Adjustable Assets | B30: =B14+B28 -> 33110.63 | C30: =BS!C24-B30 -> 146880.81
A34: Debt & Liability Structure Adjustments
A36: Particulars | B36: Adjustment | C36: Source | D36: Reason
A37: Non-Current Lease Liabilities | B37: 3054.14 | C37: Note 19 (Lease Liabilities) | D37: Reclassified as long-term funded debt obligations.
A38: Current Lease Liabilities | B38: 289.74 | C38: Note 25 (Lease Liabilities) | D38: Reclassified as near-term financial debt obligations.
A39: Creditors for Capital Goods | B39: 4497.77 | C39: Note 20 & Note 27 (Financial Liab.) | D39: Consolidated and treated as urgent short-term debt; represents expansion costs financed by suppliers.
A40: Interest Accrued and Due | B40: 152.56 | C40: Note 27 (Other Financial Liab.) | D40: Treated as an immediate short-term financial obligation.
C43: Adjusted Figures
A44: Total debt (current and non-current) | B44: =BS!C33+BS!C42+BS!C34+BS!C43 -> 41533.76
A45: Adjustable Total Debt | B45: =B37+B38+B39+B52 -> 7841.65 | C45: =B44+B45 -> 49375.41

Sheet Ratios
A1: RATIOS | B1: 2024 | C1: 2025 | D1: 2025 Adjusted | E1: 2026
A3: LIQUIDITY
A5: CURRENT RATIO | B5: =BS!B22/BS!B50 -> 1.2242745 | C5: =BS!C22/BS!C50 -> 1.2247739 | D5: =Norm!C28/BS!C50 -> 0.96392014 | E5: =BS!D22/BS!D50 -> 1.288293
A6: QUICK RATIO | B6: =(BS!B17+BS!B18+BS!B19)/BS!B50 -> 1.1140271 | C6: =(BS!C17+BS!C18+BS!C19)/BS!C50 -> 1.1293556 | D6: =(BS!C17+Norm!C26)/BS!C50 -> 0.90667572 | E6: =(BS!D17+BS!D18+BS!D19)/BS!D50 -> 1.1791861
A7: CASH RATIO | B7: =(BS!B18+BS!B19)/BS!B50 -> 1.0318655 | C7: =(BS!C18+BS!C19)/BS!C50 -> 1.0150869 | D7: =Norm!C26/BS!C50 -> 0.79240701 | E7: =(BS!D18+BS!D19)/BS!D50 -> 1.0626405
A9: PROFITABILITY
A11: GROSS MARGIN | B11: =(PL!B5-PL!B11-PL!B12)/PL!B5 -> 0.59030266 | C11: =(PL!C5-PL!C11-PL!C12)/PL!C5 -> 0.57160599 | D11: - | E11: =(PL!D5-PL!D11-PL!D12)/PL!D5 -> 0.57757193
A12: OPERATING MARGIN | B12: =PL!B19/PL!B5 -> 0.22180313 | C12: =PL!C19/PL!C5 -> 0.22626166 | E12: =PL!D19/PL!D5 -> 0.22580434
A13: EBITDA MARGIN | B13: =(PL!B20)/PL!B5 -> 0.2973523 | C13: =(PL!C20)/PL!C5 -> 0.29743493 | E13: =(PL!D20)/PL!D5 -> 0.2948596
A15: EFFICIENCY
A17: DSO | B17: =(BS!B17/PL!B5)*365 -> 5.0296892 | C17: =(BS!C17/PL!C5)*365 -> 8.208815 | E17: =(BS!D17/PL!D5)*365 -> 8.7739538
A18: DIO | B18: =(BS!B16/PL!B11)*365 -> 16.563674 | C18: =(BS!C16/PL!C11)*365 -> 14.392948 | E18: =(BS!D16/PL!D11)*365 -> 16.49615
A19: DPO | B19: =((BS!B44+BS!B45)/PL!B11)*365 -> 29.743619 | C19: =((BS!C44+BS!C45)/PL!C11)*365 -> 27.179018 | E19: =((BS!D44+BS!D45)/PL!D11)*365 -> 19.924509
A20: CCC | B20: =B19+B18+B17 -> 51.336982 | C20: =C19+C18+C17 -> 49.780781 | E20: =E19+E18+E17 -> 45.194613
A21: Asset Turnover | B21: =PL!B5/BS!B24 -> 0.84795152 | C21: =PL!C5/BS!C24 -> 0.76176567 | D21: =PL!C5/Norm!C30 -> 0.93348682 | E21: =PL!D5/BS!D24 -> 0.76674222
A22: Capex Intensity | B22: =CF!B30/PL!B5 -> -0.11350276 | C22: =CF!C30/PL!C5 -> -0.25752757 | E22: =CF!D30/PL!D5 -> -0.15904696
A24: LEVERAGE
A26: D/E | B26: =BS!B55/BS!B30 -> 0.34928819 | C26: =BS!C55/BS!C30 -> 0.38239 | D26: =Norm!C45/BS!C30 -> 0.45458593 | E26: =BS!D55/BS!D30 -> 0.30528146
A27: D/Tangible Equity | B27: - | C27: =BS!C55/Norm!C30 -> 0.28277186 | D27: =Norm!C45/Norm!C30 -> 0.33615971 | E27: -
A28: Debt/EBITDA | B28: =BS!B55/PL!B20 -> 0.85583151 | C28: =BS!C55/PL!C20 -> 1.0184414 | D28: =Norm!C45/PL!C20 -> 1.210725 | E28: =BS!D55/PL!D20 -> 0.86222483
A30: COVERAGE
A31: ICR | B31: =PL!B19/PL!B14 -> 8.2109465 | C31: =PL!C19/PL!C14 -> 9.4939299 | E31: =PL!D19/PL!D14 -> 11.172484
A32: DSCR | C32: =(PL!C20-PL!C27)/Cover!B42 -> 8.2354991 | E32: -
